<?xml version="1.0"?>
<!-- created with Phobos 1.0.1 "Capricious Choutengan" -->
<robot name="robot" xmlns:xacro="http://wiki.ros.org/xacro">

    <link name="box_arm_1_">
      <inertial>
        <origin xyz="0 0 0" rpy="0 0 0"/>
        <mass value="10.0"/>
        <inertia ixx="0.88542" ixy="0" ixz="0" iyy="0.88542" iyz="0" izz="0.10417"/>
      </inertial>
      <visual name="box_arm_1">
        <origin xyz="0 0 0" rpy="0 0 0"/>
        <geometry>
          <box size="0.25 0.25 1.0"/>
        </geometry>
        <material name="Material"/>
      </visual>
      <collision name="box_arm_1">
        <origin xyz="0 0 0" rpy="0 0 0"/>
        <geometry>
          <box size="0.25 0.25 1.0"/>
        </geometry>
      </collision>
    </link>

    <link name="box_arm_2_">
      <inertial>
        <origin xyz="0 0 0" rpy="0 0 0"/>
        <mass value="3.0"/>
        <inertia ixx="0.05208" ixy="0" ixz="0" iyy="0.96354" iyz="0" izz="0.96354"/>
      </inertial>
      <visual name="box_arm_2">
        <origin xyz="0 0 0" rpy="-1.5708 0 0"/>
        <geometry>
          <box size="0.25 0.25 1.5"/>
        </geometry>
        <material name="Material"/>
      </visual>
      <collision name="box_arm_2">
        <origin xyz="0 0 0" rpy="-1.5708 0 0"/>
        <geometry>
          <box size="0.25 0.25 1.5"/>
        </geometry>
      </collision>
    </link>

    <link name="box_arm_3_">
      <inertial>
        <origin xyz="0 0 0" rpy="0 0 0"/>
        <mass value="3.0"/>
        <inertia ixx="0.62604" ixy="0" ixz="0" iyy="0.62604" iyz="0" izz="0.05208"/>
      </inertial>
      <visual name="box_arm_3">
        <origin xyz="0 0 0" rpy="-1.5708 0 0"/>
        <geometry>
          <box size="0.25 0.25 1.2"/>
        </geometry>
        <material name="Material"/>
      </visual>
      <collision name="box_arm_3">
        <origin xyz="0 0 0" rpy="-1.5708 0 0"/>
        <geometry>
          <box size="0.25 0.25 1.2"/>
        </geometry>
      </collision>
    </link>

    <link name="box_botton">
      <inertial>
        <origin xyz="0 0 0" rpy="0 0 0"/>
        <mass value="100.0"/>
        <inertia ixx="62.5" ixy="0" ixz="0" iyy="33.61816" iyz="0" izz="0.61035"/>
      </inertial>
      <visual name="Cube.001">
        <origin xyz="0 0 0" rpy="0 0 0"/>
        <geometry>
          <box size="2.0 1.5 0.5"/>
        </geometry>
        <material name="Material.001"/>
      </visual>
      <collision name="Cube.001">
        <origin xyz="0 0 0" rpy="0 0 0"/>
        <geometry>
          <box size="2.0 1.5 0.5"/>
        </geometry>
      </collision>
    </link>

    <link name="base_link">
      <inertial>
        <origin xyz="0 0 0" rpy="0 0 0"/>
        <mass value="150.0"/>
        <inertia ixx="896.48435" ixy="0" ixz="0" iyy="385.41666" iyz="0" izz="2.11589"/>
      </inertial>
      <visual name="Cube">
        <origin xyz="0 0 0" rpy="0 0 0"/>
        <geometry>
          <box size="3.0 2.0 0.5"/>
        </geometry>
        <material name="Material"/>
      </visual>
      <collision name="Cube">
        <origin xyz="0 0 0" rpy="0 0 0"/>
        <geometry>
          <box size="3.0 2.0 0.5"/>
        </geometry>
      </collision>
    </link>

    <link name="base_footprint">
      <inertial>
        <origin xyz="0 0 0" rpy="0 0 0"/>
        <mass value="0.1"/>
        <inertia ixx="0.001" ixy="0" ixz="0" iyy="0.001" iyz="0" izz="0.001"/>
      </inertial>
    </link>


    <link name="c2_felt_front_back_">
      <inertial>
        <origin xyz="0 0 0" rpy="0 0 0"/>
        <mass value="1.5"/>
        <inertia ixx="2e-05" ixy="0" ixz="0" iyy="2e-05" iyz="0" izz="8e-05"/>
      </inertial>
      <visual name="left_front_back2">
        <origin xyz="0 0 0" rpy="0 0 0"/>
        <geometry>
          <cylinder radius="0.05" length="0.3"/>
        </geometry>
        <material name="Material.001"/>
      </visual>
      <collision name="left_front_back2">
        <origin xyz="0 0 0" rpy="0 0 0"/>
        <geometry>
          <box size="0.1 0.1 0.3"/>
        </geometry>
      </collision>
    </link>

    <link name="c2_left_back_back_">
      <inertial>
        <origin xyz="0 0 0" rpy="0 0 0"/>
        <mass value="1.5"/>
        <inertia ixx="2e-05" ixy="0" ixz="0" iyy="2e-05" iyz="0" izz="8e-05"/>
      </inertial>
      <visual name="left_back_back2">
        <origin xyz="0 0 0" rpy="0 0 0"/>
        <geometry>
          <cylinder radius="0.05" length="0.3"/>
        </geometry>
        <material name="Material.001"/>
      </visual>
      <collision name="left_back_back2">
        <origin xyz="0 0 0" rpy="0 0 0"/>
        <geometry>
          <box size="0.1 0.1 0.3"/>
        </geometry>
      </collision>
    </link>

    <link name="c2_left_back_front_">
      <inertial>
        <origin xyz="0 0 0" rpy="0 0 0"/>
        <mass value="1.5"/>
        <inertia ixx="2e-05" ixy="0" ixz="0" iyy="2e-05" iyz="0" izz="8e-05"/>
      </inertial>
      <visual name="left_back_front2">
        <origin xyz="0 0 0" rpy="0 0 0"/>
        <geometry>
          <cylinder radius="0.05" length="0.3"/>
        </geometry>
        <material name="Material.001"/>
      </visual>
      <collision name="left_back_front2">
        <origin xyz="0 0 0" rpy="0 0 0"/>
        <geometry>
          <box size="0.1 0.1 0.3"/>
        </geometry>
      </collision>
    </link>

    <link name="c2_left_front_front_">
      <inertial>
        <origin xyz="0 0 0" rpy="0 0 0"/>
        <mass value="1.5"/>
        <inertia ixx="2e-05" ixy="0" ixz="0" iyy="2e-05" iyz="0" izz="8e-05"/>
      </inertial>
      <visual name="left_front_front2">
        <origin xyz="0 0 0" rpy="0 0 0"/>
        <geometry>
          <cylinder radius="0.05" length="0.3"/>
        </geometry>
        <material name="Material.001"/>
      </visual>
      <collision name="left_front_front2">
        <origin xyz="0 0 0" rpy="0 0 0"/>
        <geometry>
          <box size="0.1 0.1 0.3"/>
        </geometry>
      </collision>
    </link>

    <link name="c2_right_back_back">
      <inertial>
        <origin xyz="0 0 0" rpy="0 0 0"/>
        <mass value="1.5"/>
        <inertia ixx="0.0125" ixy="0" ixz="0" iyy="0.0025" iyz="0" izz="0.0125"/>
      </inertial>
      <visual name="right_back_back2">
        <origin xyz="0 0 0" rpy="-3.14159 0 0"/>
        <geometry>
          <cylinder radius="0.05" length="0.3"/>
        </geometry>
        <material name="Material.001"/>
      </visual>
      <collision name="right_back_back2">
        <origin xyz="0 0 0" rpy="-3.14159 0 0"/>
        <geometry>
          <box size="0.1 0.1 0.3"/>
        </geometry>
      </collision>
    </link>

    <link name="c2_right_back_front">
      <inertial>
        <origin xyz="0 0 0" rpy="0 0 0"/>
        <mass value="1.5"/>
        <inertia ixx="2e-05" ixy="0" ixz="0" iyy="2e-05" iyz="0" izz="8e-05"/>
      </inertial>
      <visual name="right_back_front2">
        <origin xyz="0 0 0" rpy="-3.14159 0 0"/>
        <geometry>
          <cylinder radius="0.05" length="0.3"/>
        </geometry>
        <material name="Material.001"/>
      </visual>
      <collision name="right_back_front2">
        <origin xyz="0 0 0" rpy="-3.14159 0 0"/>
        <geometry>
          <box size="0.1 0.1 0.3"/>
        </geometry>
      </collision>
    </link>

    <link name="c2_right_front_back">
      <inertial>
        <origin xyz="0 0 0" rpy="0 0 0"/>
        <mass value="1.5"/>
        <inertia ixx="2e-05" ixy="0" ixz="0" iyy="2e-05" iyz="0" izz="2e-05"/>
      </inertial>
      <visual name="right_front_back2">
        <origin xyz="0 0 0" rpy="-3.14159 0 0"/>
        <geometry>
          <cylinder radius="0.05" length="0.3"/>
        </geometry>
        <material name="Material.001"/>
      </visual>
      <collision name="right_front_back2">
        <origin xyz="0 0 0" rpy="-3.14159 0 0"/>
        <geometry>
          <box size="0.1 0.1 0.3"/>
        </geometry>
      </collision>
    </link>

    <link name="c2_right_front_front">
      <inertial>
        <origin xyz="0 0 0" rpy="0 0 0"/>
        <mass value="1.5"/>
        <inertia ixx="2e-05" ixy="0" ixz="0" iyy="2e-05" iyz="0" izz="8e-05"/>
      </inertial>
      <visual name="right_front_front2">
        <origin xyz="0 0 0" rpy="-3.14159 0 0"/>
        <geometry>
          <cylinder radius="0.05" length="0.3"/>
        </geometry>
        <material name="Material.001"/>
      </visual>
      <collision name="right_front_front2">
        <origin xyz="0 0 0" rpy="-3.14159 0 0"/>
        <geometry>
          <box size="0.1 0.1 0.3"/>
        </geometry>
      </collision>
    </link>

    <link name="c_left_back_back_">
      <inertial>
        <origin xyz="0 0 0" rpy="0 0 0"/>
        <mass value="1.5"/>
        <inertia ixx="2e-05" ixy="0" ixz="-0.00024" iyy="2e-05" iyz="8e-05" izz="0.08378"/>
      </inertial>
      <visual name="Cylinder.002">
        <origin xyz="0 0 0" rpy="0 0 0"/>
        <geometry>
          <cylinder radius="0.05" length="0.94"/>
        </geometry>
        <material name="Material.001"/>
      </visual>
      <collision name="Cylinder.002">
        <origin xyz="0 0 0" rpy="0 0 0"/>
        <geometry>
          <box size="0.1 0.1 0.94"/>
        </geometry>
      </collision>
    </link>

    <link name="c_left_back_front_">
      <inertial>
        <origin xyz="0 0 0" rpy="0 0 0"/>
        <mass value="1.5"/>
        <inertia ixx="2e-05" ixy="0" ixz="-2e-05" iyy="2e-05" iyz="3e-05" izz="0.00164"/>
      </inertial>
      <visual name="Cylinder.005">
        <origin xyz="0 0 0" rpy="0 0 0"/>
        <geometry>
          <cylinder radius="0.05" length="0.55"/>
        </geometry>
        <material name="Material.001"/>
      </visual>
      <collision name="Cylinder.005">
        <origin xyz="0 0 0" rpy="0 0 0"/>
        <geometry>
          <box size="0.1 0.1 0.55"/>
        </geometry>
      </collision>
    </link>

    <link name="c_left_front_back_">
      <inertial>
        <origin xyz="0 0 0" rpy="0 0 0"/>
        <mass value="1.5"/>
        <inertia ixx="2e-05" ixy="0" ixz="2e-05" iyy="2e-05" iyz="3e-05" izz="0.00164"/>
      </inertial>
      <visual name="Cylinder.004">
        <origin xyz="0 0 0" rpy="0 0 0"/>
        <geometry>
          <cylinder radius="0.05" length="0.55"/>
        </geometry>
        <material name="Material.001"/>
      </visual>
      <collision name="Cylinder.004">
        <origin xyz="0 0 0" rpy="0 0 0"/>
        <geometry>
          <box size="0.1 0.1 0.55"/>
        </geometry>
      </collision>
    </link>

    <link name="c_left_front_front_">
      <inertial>
        <origin xyz="0 0 0" rpy="0 0 0"/>
        <mass value="1.5"/>
        <inertia ixx="2e-05" ixy="0" ixz="0.00024" iyy="2e-05" iyz="8e-05" izz="0.08378"/>
      </inertial>
      <visual name="Cylinder">
        <origin xyz="0 0 0" rpy="0 0 0"/>
        <geometry>
          <cylinder radius="0.05" length="0.94"/>
        </geometry>
        <material name="Material.001"/>
      </visual>
      <collision name="Cylinder">
        <origin xyz="0 0 0" rpy="0 0 0"/>
        <geometry>
          <box size="0.1 0.1 0.94"/>
        </geometry>
      </collision>
    </link>

    <link name="c_right_back_back_">
      <inertial>
        <origin xyz="0 0 0" rpy="0 0 0"/>
        <mass value="1.5"/>
        <inertia ixx="2e-05" ixy="0" ixz="-0.00024" iyy="2e-05" iyz="-8e-05" izz="0.08378"/>
      </inertial>
      <visual name="Cylinder.001">
        <origin xyz="0 0 0" rpy="0 0 0"/>
        <geometry>
          <cylinder radius="0.05" length="0.94"/>
        </geometry>
        <material name="Material.001"/>
      </visual>
      <collision name="Cylinder.001">
        <origin xyz="0 0 0" rpy="0 0 0"/>
        <geometry>
          <box size="0.1 0.1 0.94"/>
        </geometry>
      </collision>
    </link>

    <link name="c_right_back_front_">
      <inertial>
        <origin xyz="0 0 0" rpy="0 0 0"/>
        <mass value="1.5"/>
        <inertia ixx="2e-05" ixy="0" ixz="-2e-05" iyy="2e-05" iyz="-3e-05" izz="0.00164"/>
      </inertial>
      <visual name="Cylinder.006">
        <origin xyz="0 0 0" rpy="0 0 0"/>
        <geometry>
          <cylinder radius="0.05" length="0.55"/>
        </geometry>
        <material name="Material.001"/>
      </visual>
      <collision name="Cylinder.006">
        <origin xyz="0 0 0" rpy="0 0 0"/>
        <geometry>
          <box size="0.1 0.1 0.55"/>
        </geometry>
      </collision>
    </link>

    <link name="c_right_front_back">
      <inertial>
        <origin xyz="0 0 0" rpy="0 0 0"/>
        <mass value="1.5"/>
        <inertia ixx="2e-05" ixy="0" ixz="2e-05" iyy="2e-05" iyz="-3e-05" izz="0.00164"/>
      </inertial>
      <visual name="Cylinder.007">
        <origin xyz="0 0 0" rpy="0 0 0"/>
        <geometry>
          <cylinder radius="0.05" length="0.55"/>
        </geometry>
        <material name="Material.001"/>
      </visual>
      <collision name="Cylinder.007">
        <origin xyz="0 0 0" rpy="0 0 0"/>
        <geometry>
          <box size="0.1 0.1 0.55"/>
        </geometry>
      </collision>
    </link>

    <link name="c_right_front_front_">
      <inertial>
        <origin xyz="0 0 0" rpy="0 0 0"/>
        <mass value="1.5"/>
        <inertia ixx="2e-05" ixy="0" ixz="0.00024" iyy="2e-05" iyz="-8e-05" izz="0.08378"/>
      </inertial>
      <visual name="Cylinder.003">
        <origin xyz="0 0 0" rpy="0 0 0"/>
        <geometry>
          <cylinder radius="0.05" length="0.94"/>
        </geometry>
        <material name="Material.001"/>
      </visual>
      <collision name="Cylinder.003">
        <origin xyz="0 0 0" rpy="0 0 0"/>
        <geometry>
          <box size="0.1 0.1 0.94"/>
        </geometry>
      </collision>
    </link>

    <link name="end_effector_">
      <inertial>
        <origin xyz="0 0 0" rpy="0 0 0"/>
        <mass value="1.0"/>
        <inertia ixx="0.10417" ixy="0" ixz="0" iyy="0.10417" iyz="0" izz="0.20833"/>
      </inertial>
      <visual name="end_effector">
        <origin xyz="0 0 0" rpy="0 0 0"/>
        <geometry>
          <box size="0.6 0.6 0"/>
        </geometry>
        <material name="Material"/>
      </visual>
      <collision name="end_effector">
        <origin xyz="0 0 0" rpy="0 0 0"/>
        <geometry>
          <box size="0.6 0.6 0"/>
        </geometry>
      </collision>
    </link>

    <link name="end_effector_back_">
      <inertial>
        <origin xyz="0 0 0" rpy="0 0 0"/>
        <mass value="2.0"/>
        <inertia ixx="0.04688" ixy="0" ixz="0" iyy="0.00938" iyz="0" izz="0.0375"/>
      </inertial>
      <visual name="end_effector_back">
        <origin xyz="0 -0.05 0" rpy="-1.5708 0 0"/>
        <geometry>
          <box size="0.15 0.3 0"/>
        </geometry>
        <material name="phobos_indicator5"/>
      </visual>
      <collision name="end_effector_back">
        <origin xyz="0 -0.05 0" rpy="-1.5708 0 0"/>
        <geometry>
          <box size="0.15 0.3 0"/>
        </geometry>
      </collision>
    </link>

    <link name="end_effector_left_">
      <inertial>
        <origin xyz="0 0 0" rpy="0 0 0"/>
        <mass value="2.0"/>
        <inertia ixx="0.00938" ixy="0" ixz="0" iyy="0.04688" iyz="0" izz="0.0375"/>
      </inertial>
      <visual name="end_effector_left">
        <origin xyz="-0.04 0 0" rpy="0 1.5708 0"/>
        <geometry>
          <box size="0.3 0.15 0"/>
        </geometry>
        <material name="phobos_indicator5"/>
      </visual>
      <collision name="end_effector_left">
        <origin xyz="-0.04 0 0" rpy="0 1.5708 0"/>
        <geometry>
          <box size="0.3 0.15 0"/>
        </geometry>
      </collision>
    </link>

    <link name="end_effector_right_">
      <inertial>
        <origin xyz="0 0 0" rpy="0 0 0"/>
        <mass value="2.0"/>
        <inertia ixx="0.00938" ixy="0" ixz="0" iyy="0.04688" iyz="0" izz="0.0375"/>
      </inertial>
      <visual name="end_effector_right">
        <origin xyz="-0.04 0 0" rpy="0 -1.5708 0"/>
        <geometry>
          <box size="0.3 0.15 0"/>
        </geometry>
        <material name="phobos_indicator5"/>
      </visual>
      <collision name="end_effector_right">
        <origin xyz="-0.04 0 0" rpy="0 -1.5708 0"/>
        <geometry>
          <box size="0.3 0.15 0"/>
        </geometry>
      </collision>
    </link>

    <link name="end_effector_top_">
      <inertial>
        <origin xyz="0 0 0" rpy="0 0 0"/>
        <mass value="2.0"/>
        <inertia ixx="0.0375" ixy="0" ixz="0" iyy="0.04688" iyz="0" izz="0.00938"/>
      </inertial>
      <visual name="end_effector_top">
        <origin xyz="0.05 0 0" rpy="1.5708 0 1.5708"/>
        <geometry>
          <box size="0.15 0.3 0"/>
        </geometry>
        <material name="phobos_indicator5"/>
      </visual>
      <collision name="end_effector_top">
        <origin xyz="0.05 0 0" rpy="1.5708 0 1.5708"/>
        <geometry>
          <box size="0.15 0.3 0"/>
        </geometry>
      </collision>
    </link>

    <link name="sphere_arm_1_">
      <inertial>
        <origin xyz="0 0 0" rpy="0 0 0"/>
        <mass value="10.0"/>
        <inertia ixx="0.00488" ixy="0" ixz="0" iyy="0.00488" iyz="0" izz="0.00488"/>
      </inertial>
      <visual name="sphere_arm_1">
        <origin xyz="0 0 0" rpy="0 0 0"/>
        <geometry>
          <sphere radius="0.25"/>
        </geometry>
        <material name="Material.001"/>
      </visual>
      <collision name="sphere_arm_1">
        <origin xyz="0 0 0" rpy="0 0 0"/>
        <geometry>
          <box size="0.5 0.5 0.5"/>
        </geometry>
      </collision>
    </link>

    <link name="sphere_arm_2_">
      <inertial>
        <origin xyz="0 0 0" rpy="0 0 0"/>
        <mass value="5.0"/>
        <inertia ixx="0.00049" ixy="0" ixz="0" iyy="0.00049" iyz="0" izz="0.00049"/>
      </inertial>
      <visual name="sphere_arm_2">
        <origin xyz="0 0 0" rpy="0 0 0"/>
        <geometry>
          <sphere radius="0.25"/>
        </geometry>
        <material name="Material"/>
      </visual>
      <collision name="sphere_arm_2">
        <origin xyz="0 0 0" rpy="0 0 0"/>
        <geometry>
          <box size="0.5 0.5 0.5"/>
        </geometry>
      </collision>
    </link>

    <link name="wall_back_">
      <inertial>
        <origin xyz="0 0 0" rpy="0 0 0"/>
        <mass value="0.1"/>
        <inertia ixx="1.58854" ixy="0" ixz="0" iyy="0.9375" iyz="0" izz="0.65104"/>
      </inertial>
      <visual name="wall_back">
        <origin xyz="0 0 0" rpy="0 0 0"/>
        <geometry>
          <box size="1.5 1.25 0"/>
        </geometry>
        <material name="phobos_controller"/>
      </visual>
      <collision name="wall_back">
        <origin xyz="0 0 0" rpy="0 0 0"/>
        <geometry>
          <box size="1.5 1.25 0"/>
        </geometry>
      </collision>
    </link>

    <link name="wall_left_">
      <inertial>
        <origin xyz="0 0 0" rpy="0 0 0"/>
        <mass value="0.1"/>
        <inertia ixx="0.9375" ixy="0" ixz="0" iyy="1.875" iyz="0" izz="0.9375"/>
      </inertial>
      <visual name="wall_left">
        <origin xyz="0 0 0" rpy="0 0 0"/>
        <geometry>
          <box size="1.5 1.5 0"/>
        </geometry>
        <material name="phobos_controller"/>
      </visual>
      <collision name="wall_left">
        <origin xyz="0 0 0" rpy="0 0 0"/>
        <geometry>
          <box size="1.5 1.5 0"/>
        </geometry>
      </collision>
    </link>

    <link name="wall_ramp_">
      <inertial>
        <origin xyz="0 0 0" rpy="0 0 0"/>
        <mass value="0.1"/>
        <inertia ixx="0.65821" ixy="0" ixz="-0.08194" iyy="0.94376" iyz="0" izz="1.58763"/>
      </inertial>
      <visual name="wall_ramp">
        <origin xyz="0 0 0" rpy="0 0 0"/>
        <geometry>
          <box size="1.505 1.25 0"/>
        </geometry>
      </visual>
      <collision name="wall_ramp">
        <origin xyz="0 0 0" rpy="0 0 0"/>
        <geometry>
          <box size="1.505 1.25 0"/>
        </geometry>
      </collision>
    </link>

    <link name="wall_right_">
      <inertial>
        <origin xyz="0 0 0" rpy="0 0 0"/>
        <mass value="0.1"/>
        <inertia ixx="0.9375" ixy="0" ixz="0" iyy="1.875" iyz="0" izz="0.9375"/>
      </inertial>
      <visual name="wall_right">
        <origin xyz="0 0 0" rpy="0 0 0"/>
        <geometry>
          <box size="1.5 1.5 0"/>
        </geometry>
        <material name="phobos_controller"/>
      </visual>
      <collision name="wall_right">
        <origin xyz="0 0 0" rpy="0 0 0"/>
        <geometry>
          <box size="1.5 1.5 0"/>
        </geometry>
      </collision>
    </link>

    <link name="wall_top_">
      <inertial>
        <origin xyz="0 0 0" rpy="0 0 0"/>
        <mass value="0.1"/>
        <inertia ixx="1.58854" ixy="0" ixz="0" iyy="0.9375" iyz="0" izz="0.65104"/>
      </inertial>
      <visual name="wall_top">
        <origin xyz="0 0 0" rpy="0 0 0"/>
        <geometry>
          <box size="1.5 1.25 0"/>
        </geometry>
        <material name="phobos_controller"/>
      </visual>
      <collision name="wall_top">
        <origin xyz="0 0 0" rpy="0 0 0"/>
        <geometry>
          <box size="1.5 1.25 0"/>
        </geometry>
      </collision>
    </link>

    <link name="wheel_left_back_back_">
      <inertial>
        <origin xyz="0 0 0" rpy="0 0 0"/>
        <mass value="10.0"/>
        <inertia ixx="0.0201" ixy="0" ixz="0" iyy="0.03887" iyz="0" izz="0.49015"/>
      </inertial>
      <visual name="wheel_left_back_back">
        <origin xyz="0 0 0" rpy="-3.14159 0 0"/>
        <geometry>
          <mesh filename="file://$(find practica3)/meshes/dae/Torus.003.dae" scale="0.27 0.27 0.6"/>
        </geometry>
        <material name="Material.001"/>
      </visual>
      <collision name="wheel_left_back_back.000">
        <origin xyz="0 0 0" rpy="-3.14159 0 0"/>
        <geometry>
          <mesh filename="file://$(find practica3)/meshes/dae/Torus.011.dae" scale="1.0 1.0 1.0"/>
        </geometry>
      </collision>
    </link>

    <link name="wheel_left_back_front_">
      <inertial>
        <origin xyz="0 0 0" rpy="0 0 0"/>
        <mass value="10.0"/>
        <inertia ixx="0.0201" ixy="0" ixz="0" iyy="0.03887" iyz="0" izz="0.49015"/>
      </inertial>
      <visual name="wheel_left_back_front">
        <origin xyz="0 0 0" rpy="-3.14159 0 0"/>
        <geometry>
          <mesh filename="file://$(find practica3)/meshes/dae/Torus.007.dae" scale="0.27 0.27 0.6"/>
        </geometry>
        <material name="Material.001"/>
      </visual>
      <collision name="wheel_left_back_front.000">
        <origin xyz="0 0 0" rpy="-3.14159 0 0"/>
        <geometry>
          <mesh filename="file://$(find practica3)/meshes/dae/Torus.010.dae" scale="1.0 1.0 1.0"/>
        </geometry>
      </collision>
    </link>

    <link name="wheel_left_front_back_">
      <inertial>
        <origin xyz="0 0 0" rpy="0 0 0"/>
        <mass value="10.0"/>
        <inertia ixx="0.0201" ixy="0" ixz="0" iyy="0.03887" iyz="0" izz="0.49015"/>
      </inertial>
      <visual name="wheel_left_front_back">
        <origin xyz="0 0 0" rpy="-3.14159 0 0"/>
        <geometry>
          <mesh filename="file://$(find practica3)/meshes/dae/Torus.005.dae" scale="0.27 0.27 0.6"/>
        </geometry>
        <material name="Material.001"/>
      </visual>
      <collision name="wheel_left_front_back.000">
        <origin xyz="0 0 0" rpy="-3.14159 0 0"/>
        <geometry>
          <mesh filename="file://$(find practica3)/meshes/dae/Torus.009.dae" scale="1.0 1.0 1.0"/>
        </geometry>
      </collision>
    </link>

    <link name="wheel_left_front_front_">
      <inertial>
        <origin xyz="0 0 0" rpy="0 0 0"/>
        <mass value="10.0"/>
        <inertia ixx="0.0201" ixy="0" ixz="0" iyy="0.03887" iyz="0" izz="0.49015"/>
      </inertial>
      <visual name="wheel_left_front_front">
        <origin xyz="0 0 0" rpy="-3.14159 0 0"/>
        <geometry>
          <mesh filename="file://$(find practica3)/meshes/dae/Torus.dae" scale="0.27 0.27 0.6"/>
        </geometry>
        <material name="Material.001"/>
      </visual>
      <collision name="wheel_left_front_front.000">
        <origin xyz="0 0 0" rpy="-3.14159 0 0"/>
        <geometry>
          <mesh filename="file://$(find practica3)/meshes/dae/Torus.008.dae" scale="1.0 1.0 1.0"/>
        </geometry>
      </collision>
    </link>

    <link name="wheel_right_back_back_">
      <inertial>
        <origin xyz="0 0 0" rpy="0 0 0"/>
        <mass value="10.0"/>
        <inertia ixx="0.0201" ixy="0" ixz="0" iyy="0.03887" iyz="0" izz="0.49015"/>
      </inertial>
      <visual name="wheel_right_back_back">
        <origin xyz="0 0 0" rpy="0 0 0"/>
        <geometry>
          <mesh filename="file://$(find practica3)/meshes/dae/Torus.002.dae" scale="0.27 0.27 0.6"/>
        </geometry>
        <material name="Material.001"/>
      </visual>
      <collision name="wheel_right_back_back.000">
        <origin xyz="0 0 0" rpy="0 0 0"/>
        <geometry>
          <mesh filename="file://$(find practica3)/meshes/dae/Torus.012.dae" scale="1.0 1.0 1.0"/>
        </geometry>
      </collision>
    </link>

    <link name="wheel_right_back_front_">
      <inertial>
        <origin xyz="0 0 0" rpy="0 0 0"/>
        <mass value="10.0"/>
        <inertia ixx="0.0201" ixy="0" ixz="0" iyy="0.03887" iyz="0" izz="0.49015"/>
      </inertial>
      <visual name="wheel_right_back_front">
        <origin xyz="0 0 0" rpy="0 0 0"/>
        <geometry>
          <mesh filename="file://$(find practica3)/meshes/dae/Torus.006.dae" scale="0.27 0.27 0.6"/>
        </geometry>
        <material name="Material.001"/>
      </visual>
      <collision name="wheel_right_back_front.000">
        <origin xyz="0 0 0" rpy="0 0 0"/>
        <geometry>
          <mesh filename="file://$(find practica3)/meshes/dae/Torus.013.dae" scale="1.0 1.0 1.0"/>
        </geometry>
      </collision>
    </link>

    <link name="wheel_right_front_back_">
      <inertial>
        <origin xyz="0 0 0" rpy="0 0 0"/>
        <mass value="10.0"/>
        <inertia ixx="0.0201" ixy="0" ixz="0" iyy="0.03887" iyz="0" izz="0.49015"/>
      </inertial>
      <visual name="wheel_right_front_back">
        <origin xyz="0 0 0" rpy="0 0 0"/>
        <geometry>
          <mesh filename="file://$(find practica3)/meshes/dae/Torus.004.dae" scale="0.27 0.27 0.6"/>
        </geometry>
        <material name="Material.001"/>
      </visual>
      <collision name="wheel_right_front_back.000">
        <origin xyz="0 0 0" rpy="0 0 0"/>
        <geometry>
          <mesh filename="file://$(find practica3)/meshes/dae/Torus.014.dae" scale="1.0 1.0 1.0"/>
        </geometry>
      </collision>
    </link>

    <link name="wheel_right_front_front_">
      <inertial>
        <origin xyz="0 0 0" rpy="0 0 0"/>
        <mass value="10.0"/>
        <inertia ixx="0.0201" ixy="0" ixz="0" iyy="0.0201" iyz="0" izz="0.94798"/>
      </inertial>
      <visual name="wheel_right_front_front">
        <origin xyz="0 0 0" rpy="0 0 0"/>
        <geometry>
          <mesh filename="file://$(find practica3)/meshes/dae/Torus.001.dae" scale="0.27 0.27 0.6"/>
        </geometry>
        <material name="Material.001"/>
      </visual>
      <collision name="wheel_right_front_front.000">
        <origin xyz="0 0 0" rpy="0 0 0"/>
        <geometry>
          <mesh filename="file://$(find practica3)/meshes/dae/Torus.015.dae" scale="0.27 0.27 0.6"/>
        </geometry>
      </collision>
    </link>

    <joint name="base_link_" type="fixed">
      <origin xyz="0 0 1.235" rpy="0 0 0"/>
      <parent link="base_footprint"/>
      <child link="base_link"/>
    </joint>

    <joint name="box_arm_1_" type="continuous">
      <origin xyz="1.37 0 0.75" rpy="0 0 0"/>
      <parent link="base_link"/>
      <child link="box_arm_1_"/>
      <axis xyz="0 0 1.0"/>
      <limit effort="0" velocity="0"/>
    </joint>

    <joint name="box_arm_2_" type="fixed">
      <origin xyz="0.75 0 0" rpy="0 0 -1.5708"/>
      <parent link="sphere_arm_1_"/>
      <child link="box_arm_2_"/>
    </joint>

    <joint name="box_arm_3_" type="fixed">
      <origin xyz="0 -0.65 0" rpy="0 0 0"/>
      <parent link="sphere_arm_2_"/>
      <child link="box_arm_3_"/>
    </joint>

    <joint name="box_botton" type="fixed">
      <origin xyz="0 0 -0.25" rpy="0 0 0"/>
      <parent link="base_link"/>
      <child link="box_botton"/>
    </joint>

    <joint name="c2_felt_front_back_" type="fixed">
      <origin xyz="0.58 0.8 -0.9" rpy="1.5708 0 0"/>
      <parent link="base_link"/>
      <child link="c2_felt_front_back_"/>
    </joint>

    <joint name="c2_left_back_back_" type="fixed">
      <origin xyz="-1.62 0.8 -0.9" rpy="1.5708 0 0"/>
      <parent link="base_link"/>
      <child link="c2_left_back_back_"/>
    </joint>

    <joint name="c2_left_back_front_" type="fixed">
      <origin xyz="-0.58 0.8 -0.9" rpy="1.5708 0 0"/>
      <parent link="base_link"/>
      <child link="c2_left_back_front_"/>
    </joint>

    <joint name="c2_left_front_front_" type="fixed">
      <origin xyz="1.62 0.8 -0.9" rpy="1.5708 0 0"/>
      <parent link="base_link"/>
      <child link="c2_left_front_front_"/>
    </joint>

    <joint name="c2_right_back_back" type="fixed">
      <origin xyz="-1.62 -0.8 -0.9" rpy="-1.5708 0 0"/>
      <parent link="base_link"/>
      <child link="c2_right_back_back"/>
    </joint>

    <joint name="c2_right_back_front" type="fixed">
      <origin xyz="-0.58 -0.8 -0.9" rpy="-1.5708 0 0"/>
      <parent link="base_link"/>
      <child link="c2_right_back_front"/>
    </joint>

    <joint name="c2_right_front_back" type="fixed">
      <origin xyz="0.58 -0.8 -0.9" rpy="-1.5708 0 0"/>
      <parent link="base_link"/>
      <child link="c2_right_front_back"/>
    </joint>

    <joint name="c2_right_front_front" type="fixed">
      <origin xyz="1.62 -0.8 -0.9" rpy="-1.5708 0 0"/>
      <parent link="base_link"/>
      <child link="c2_right_front_front"/>
    </joint>

    <joint name="c_left_back_back_" type="fixed">
      <origin xyz="-1.25 0.57 -0.7" rpy="0.2618 1.0472 0"/>
      <parent link="base_link"/>
      <child link="c_left_back_back_"/>
    </joint>

    <joint name="c_left_back_front_" type="fixed">
      <origin xyz="-0.5 0.57 -0.7" rpy="0.5236 0.34907 0"/>
      <parent link="base_link"/>
      <child link="c_left_back_front_"/>
    </joint>

    <joint name="c_left_front_back_" type="fixed">
      <origin xyz="0.5 0.57 -0.7" rpy="0.5236 -0.34907 0"/>
      <parent link="base_link"/>
      <child link="c_left_front_back_"/>
    </joint>

    <joint name="c_left_front_front_" type="fixed">
      <origin xyz="1.25 0.57 -0.7" rpy="0.2618 -1.0472 0"/>
      <parent link="base_link"/>
      <child link="c_left_front_front_"/>
    </joint>

    <joint name="c_right_back_back_" type="fixed">
      <origin xyz="-1.25 -0.57 -0.7" rpy="-0.2618 1.0472 0"/>
      <parent link="base_link"/>
      <child link="c_right_back_back_"/>
    </joint>

    <joint name="c_right_back_front_" type="fixed">
      <origin xyz="-0.5 -0.57 -0.7" rpy="-0.5236 0.34907 0"/>
      <parent link="base_link"/>
      <child link="c_right_back_front_"/>
    </joint>

    <joint name="c_right_front_back" type="fixed">
      <origin xyz="0.5 -0.57 -0.7" rpy="-0.5236 -0.34907 0"/>
      <parent link="base_link"/>
      <child link="c_right_front_back"/>
    </joint>

    <joint name="c_right_front_front_" type="fixed">
      <origin xyz="1.25 -0.57 -0.7" rpy="-0.2618 -1.0472 0"/>
      <parent link="base_link"/>
      <child link="c_right_front_front_"/>
    </joint>

    <joint name="end_effector_" type="fixed">
      <origin xyz="0 -0.6 0" rpy="-1.5708 0 0"/>
      <parent link="box_arm_3_"/>
      <child link="end_effector_"/>
    </joint>

    <joint name="end_effector_back_" type="revolute">
      <origin xyz="-0.22 0 -0.08" rpy="1.5708 1.5708 0"/>
      <parent link="end_effector_"/>
      <child link="end_effector_back_"/>
      <axis xyz="0 0 1.0"/>
      <limit lower="0" upper="0.32" effort="0" velocity="0"/>
    </joint>

    <joint name="end_effector_left_" type="revolute">
      <origin xyz="0 0.225 -0.08" rpy="1.5708 0 -1.5708"/>
      <parent link="end_effector_"/>
      <child link="end_effector_left_"/>
      <axis xyz="0 0 1.0"/>
      <limit lower="0" upper="0.32" effort="0" velocity="0"/>
    </joint>

    <joint name="end_effector_right_" type="revolute">
      <origin xyz="0 -0.225 -0.08" rpy="1.5708 0 1.5708"/>
      <parent link="end_effector_"/>
      <child link="end_effector_right_"/>
      <axis xyz="0 0 1.0"/>
      <limit lower="0" upper="0.32" effort="0" velocity="0"/>
    </joint>

    <joint name="end_effector_top_" type="revolute">
      <origin xyz="0.22 0 -0.08" rpy="-1.5708 0 0"/>
      <parent link="end_effector_"/>
      <child link="end_effector_top_"/>
      <axis xyz="0 0 1.0"/>
      <limit lower="0" upper="0.32" effort="0" velocity="0"/>
    </joint>

    <joint name="sphere_arm_1_" type="revolute">
      <origin xyz="0 0 0.5" rpy="1.5708 0 0"/>
      <parent link="box_arm_1_"/>
      <child link="sphere_arm_1_"/>
      <axis xyz="0 0 1.0"/>
      <limit lower="-0.6" upper="1.57" effort="0" velocity="0"/>
    </joint>

    <joint name="sphere_arm_2_" type="revolute">
      <origin xyz="0 0.75 0" rpy="0 0 1.5708"/>
      <parent link="box_arm_2_"/>
      <child link="sphere_arm_2_"/>
      <axis xyz="0 0 1.0"/>
      <limit lower="0" upper="1.57" effort="0" velocity="0"/>
    </joint>

    <joint name="wall_back_" type="fixed">
      <origin xyz="-1.4 0 1.0" rpy="0 1.5708 0"/>
      <parent link="base_link"/>
      <child link="wall_back_"/>
    </joint>

    <joint name="wall_left_" type="fixed">
      <origin xyz="-0.65 0.625 1.0" rpy="1.5708 0 0"/>
      <parent link="base_link"/>
      <child link="wall_left_"/>
    </joint>

    <joint name="wall_ramp_" type="fixed">
      <origin xyz="-0.65 0 0.32" rpy="0 -0.08727 0"/>
      <parent link="base_link"/>
      <child link="wall_ramp_"/>
    </joint>

    <joint name="wall_right_" type="fixed">
      <origin xyz="-0.65 -0.625 1.0" rpy="-1.5708 0 0"/>
      <parent link="base_link"/>
      <child link="wall_right_"/>
    </joint>

    <joint name="wall_top_" type="fixed">
      <origin xyz="0.1 0 1.0" rpy="0 1.5708 0"/>
      <parent link="base_link"/>
      <child link="wall_top_"/>
    </joint>

    <joint name="wheel_left_back_back_" type="continuous">
      <origin xyz="-1.62 0.84 -0.9" rpy="-1.5708 0 0"/>
      <parent link="base_link"/>
      <child link="wheel_left_back_back_"/>
      <axis xyz="0 0 1.0"/>
      <limit effort="0" velocity="0"/>
    </joint>

    <joint name="wheel_left_back_front_" type="continuous">
      <origin xyz="-0.58 0.84 -0.9" rpy="-1.5708 0 0"/>
      <parent link="base_link"/>
      <child link="wheel_left_back_front_"/>
      <axis xyz="0 0 1.0"/>
      <limit effort="0" velocity="0"/>
    </joint>

    <joint name="wheel_left_front_back_" type="continuous">
      <origin xyz="0.58 0.84 -0.9" rpy="-1.5708 0 0"/>
      <parent link="base_link"/>
      <child link="wheel_left_front_back_"/>
      <axis xyz="0 0 1.0"/>
      <limit effort="0" velocity="0"/>
    </joint>

    <joint name="wheel_left_front_front_" type="continuous">
      <origin xyz="1.62 0.84 -0.9" rpy="-1.5708 0 0"/>
      <parent link="base_link"/>
      <child link="wheel_left_front_front_"/>
      <axis xyz="0 0 1.0"/>
      <limit effort="0" velocity="0"/>
    </joint>

    <joint name="wheel_right_back_back_" type="continuous">
      <origin xyz="-1.62 -0.84 -0.9" rpy="-1.5708 0 3.14159"/>
      <parent link="base_link"/>
      <child link="wheel_right_back_back_"/>
      <axis xyz="0 0 1.0"/>
      <limit effort="0" velocity="0"/>
    </joint>

    <joint name="wheel_right_back_front_" type="continuous">
      <origin xyz="-0.58 -0.84 -0.9" rpy="-1.5708 0 3.14159"/>
      <parent link="base_link"/>
      <child link="wheel_right_back_front_"/>
      <axis xyz="0 0 1.0"/>
      <limit effort="0" velocity="0"/>
    </joint>

    <joint name="wheel_right_front_back_" type="continuous">
      <origin xyz="0.58 -0.84 -0.9" rpy="-1.5708 0 3.14159"/>
      <parent link="base_link"/>
      <child link="wheel_right_front_back_"/>
      <axis xyz="0 0 1.0"/>
      <limit effort="0" velocity="0"/>
    </joint>

    <joint name="wheel_right_front_front_" type="continuous">
      <origin xyz="1.62 -0.84 -0.9" rpy="-1.5708 0 3.14159"/>
      <parent link="base_link"/>
      <child link="wheel_right_front_front_"/>
      <axis xyz="0 0 1.0"/>
      <limit effort="0" velocity="0"/>
    </joint>

    <xacro:include filename="$(find practica3)/urdf/sensor_imu.urdf.xacro" />
    <xacro:arg name="robot_ns" default="" />
    <xacro:arg name="prefix" default="" />

    <xacro:sensor_camera node_name="front_camera" node_namespace="$(arg robot_ns)" frame_prefix="$(arg prefix)front_camera_" parent="$(arg prefix)base_link" >
    <origin xyz="1.4 0.0 0.5" rpy="0 0 0"/>
    </xacro:sensor_camera>
    <xacro:sensor_camera node_name="arm_camera" node_namespace="$(arg robot_ns)" frame_prefix="$(arg prefix)arm_camera_" parent="$(arg prefix)end_effector_" >
    <origin xyz="0.0 0.0 -0.01" rpy="0 3.141592 0"/>
    </xacro:sensor_camera>
    <xacro:sensor_imu ns="$(arg robot_ns)" prefix="$(arg prefix)imu_" parent="$(arg prefix)base_link">
    <origin xyz="0.0 0.0 0.0" rpy="0 0 0"/>
    </xacro:sensor_imu>

    <material name="Material">
      <color rgba="0.64 0.35768 0.20581 1.0"/>
    </material>

    <material name="Material.001">
      <color rgba="0.24647 0.16006 0.04816 1.0"/>
    </material>

    <material name="phobos_controller">
      <color rgba="0.3626 0.2548 0.56 0.30000000000000004"/>
    </material>

    <material name="phobos_indicator5">
      <color rgba="1.0 1.0 0 1.0"/>
    </material>

  </robot>
